[2024-08-27T06:01:41.782+0000] {local_task_job_runner.py:123} INFO - ::group::Pre task execution logs
[2024-08-27T06:01:41.835+0000] {taskinstance.py:2603} INFO - Dependencies all met for dep_context=non-requeueable deps ti=<TaskInstance: Spark.geo_map_plot manual__2024-08-27T06:01:39.299233+00:00 [queued]>
[2024-08-27T06:01:41.855+0000] {taskinstance.py:2603} INFO - Dependencies all met for dep_context=requeueable deps ti=<TaskInstance: Spark.geo_map_plot manual__2024-08-27T06:01:39.299233+00:00 [queued]>
[2024-08-27T06:01:41.856+0000] {taskinstance.py:2856} INFO - Starting attempt 1 of 1
[2024-08-27T06:01:41.887+0000] {taskinstance.py:2879} INFO - Executing <Task(PythonOperator): geo_map_plot> on 2024-08-27 06:01:39.299233+00:00
[2024-08-27T06:01:41.900+0000] {logging_mixin.py:190} WARNING - /home/***/.local/lib/python3.12/site-packages/***/task/task_runner/standard_task_runner.py:70 DeprecationWarning: This process (pid=1506) is multi-threaded, use of fork() may lead to deadlocks in the child.
[2024-08-27T06:01:41.902+0000] {standard_task_runner.py:72} INFO - Started process 1511 to run task
[2024-08-27T06:01:41.900+0000] {standard_task_runner.py:104} INFO - Running: ['***', 'tasks', 'run', 'Spark', 'geo_map_plot', 'manual__2024-08-27T06:01:39.299233+00:00', '--job-id', '254', '--raw', '--subdir', 'DAGS_FOLDER/Seoul_spark.py', '--cfg-path', '/tmp/tmpzjhh3cwg']
[2024-08-27T06:01:41.904+0000] {standard_task_runner.py:105} INFO - Job 254: Subtask geo_map_plot
[2024-08-27T06:01:41.984+0000] {task_command.py:467} INFO - Running <TaskInstance: Spark.geo_map_plot manual__2024-08-27T06:01:39.299233+00:00 [running]> on host 1c1d52fdfc5f
[2024-08-27T06:01:42.176+0000] {taskinstance.py:3122} INFO - Exporting env vars: AIRFLOW_CTX_DAG_OWNER='***' AIRFLOW_CTX_DAG_ID='Spark' AIRFLOW_CTX_TASK_ID='geo_map_plot' AIRFLOW_CTX_EXECUTION_DATE='2024-08-27T06:01:39.299233+00:00' AIRFLOW_CTX_TRY_NUMBER='1' AIRFLOW_CTX_DAG_RUN_ID='manual__2024-08-27T06:01:39.299233+00:00'
[2024-08-27T06:01:42.178+0000] {taskinstance.py:731} INFO - ::endgroup::
[2024-08-27T06:01:42.221+0000] {taskinstance.py:3301} ERROR - Task failed with exception
Traceback (most recent call last):
  File "/home/airflow/.local/lib/python3.12/site-packages/airflow/models/taskinstance.py", line 767, in _execute_task
    result = _execute_callable(context=context, **execute_callable_kwargs)
             ^^^^^^^^^^^^^^^^^^^^^^^^^^^^^^^^^^^^^^^^^^^^^^^^^^^^^^^^^^^^^
  File "/home/airflow/.local/lib/python3.12/site-packages/airflow/models/taskinstance.py", line 733, in _execute_callable
    return ExecutionCallableRunner(
           ^^^^^^^^^^^^^^^^^^^^^^^^
  File "/home/airflow/.local/lib/python3.12/site-packages/airflow/utils/operator_helpers.py", line 252, in run
    return self.func(*args, **kwargs)
           ^^^^^^^^^^^^^^^^^^^^^^^^^^
  File "/home/airflow/.local/lib/python3.12/site-packages/airflow/models/baseoperator.py", line 406, in wrapper
    return func(self, *args, **kwargs)
           ^^^^^^^^^^^^^^^^^^^^^^^^^^^
  File "/home/airflow/.local/lib/python3.12/site-packages/airflow/operators/python.py", line 238, in execute
    return_value = self.execute_callable()
                   ^^^^^^^^^^^^^^^^^^^^^^^
  File "/home/airflow/.local/lib/python3.12/site-packages/airflow/operators/python.py", line 256, in execute_callable
    return runner.run(*self.op_args, **self.op_kwargs)
           ^^^^^^^^^^^^^^^^^^^^^^^^^^^^^^^^^^^^^^^^^^^
  File "/home/airflow/.local/lib/python3.12/site-packages/airflow/utils/operator_helpers.py", line 252, in run
    return self.func(*args, **kwargs)
           ^^^^^^^^^^^^^^^^^^^^^^^^^^
  File "/opt/airflow/dags/Seoul_spark.py", line 127, in _geomerge_plot
    import geopandas as gpd
ModuleNotFoundError: No module named 'geopandas'
[2024-08-27T06:01:42.239+0000] {taskinstance.py:1225} INFO - Marking task as FAILED. dag_id=Spark, task_id=geo_map_plot, run_id=manual__2024-08-27T06:01:39.299233+00:00, execution_date=20240827T060139, start_date=20240827T060141, end_date=20240827T060142
[2024-08-27T06:01:42.260+0000] {taskinstance.py:340} INFO - ::group::Post task execution logs
[2024-08-27T06:01:42.261+0000] {standard_task_runner.py:124} ERROR - Failed to execute job 254 for task geo_map_plot (No module named 'geopandas'; 1511)
Traceback (most recent call last):
  File "/home/airflow/.local/lib/python3.12/site-packages/airflow/task/task_runner/standard_task_runner.py", line 117, in _start_by_fork
    ret = args.func(args, dag=self.dag)
          ^^^^^^^^^^^^^^^^^^^^^^^^^^^^^
  File "/home/airflow/.local/lib/python3.12/site-packages/airflow/cli/cli_config.py", line 49, in command
    return func(*args, **kwargs)
           ^^^^^^^^^^^^^^^^^^^^^
  File "/home/airflow/.local/lib/python3.12/site-packages/airflow/utils/cli.py", line 115, in wrapper
    return f(*args, **kwargs)
           ^^^^^^^^^^^^^^^^^^
  File "/home/airflow/.local/lib/python3.12/site-packages/airflow/cli/commands/task_command.py", line 483, in task_run
    task_return_code = _run_task_by_selected_method(args, _dag, ti)
                       ^^^^^^^^^^^^^^^^^^^^^^^^^^^^^^^^^^^^^^^^^^^^
  File "/home/airflow/.local/lib/python3.12/site-packages/airflow/cli/commands/task_command.py", line 256, in _run_task_by_selected_method
    return _run_raw_task(args, ti)
           ^^^^^^^^^^^^^^^^^^^^^^^
  File "/home/airflow/.local/lib/python3.12/site-packages/airflow/cli/commands/task_command.py", line 341, in _run_raw_task
    return ti._run_raw_task(
           ^^^^^^^^^^^^^^^^^
  File "/home/airflow/.local/lib/python3.12/site-packages/airflow/utils/session.py", line 97, in wrapper
    return func(*args, session=session, **kwargs)
           ^^^^^^^^^^^^^^^^^^^^^^^^^^^^^^^^^^^^^^
  File "/home/airflow/.local/lib/python3.12/site-packages/airflow/models/taskinstance.py", line 2995, in _run_raw_task
    return _run_raw_task(
           ^^^^^^^^^^^^^^
  File "/home/airflow/.local/lib/python3.12/site-packages/airflow/models/taskinstance.py", line 273, in _run_raw_task
    TaskInstance._execute_task_with_callbacks(
  File "/home/airflow/.local/lib/python3.12/site-packages/airflow/models/taskinstance.py", line 3149, in _execute_task_with_callbacks
    result = self._execute_task(context, task_orig)
             ^^^^^^^^^^^^^^^^^^^^^^^^^^^^^^^^^^^^^^
  File "/home/airflow/.local/lib/python3.12/site-packages/airflow/models/taskinstance.py", line 3173, in _execute_task
    return _execute_task(self, context, task_orig)
           ^^^^^^^^^^^^^^^^^^^^^^^^^^^^^^^^^^^^^^^
  File "/home/airflow/.local/lib/python3.12/site-packages/airflow/models/taskinstance.py", line 767, in _execute_task
    result = _execute_callable(context=context, **execute_callable_kwargs)
             ^^^^^^^^^^^^^^^^^^^^^^^^^^^^^^^^^^^^^^^^^^^^^^^^^^^^^^^^^^^^^
  File "/home/airflow/.local/lib/python3.12/site-packages/airflow/models/taskinstance.py", line 733, in _execute_callable
    return ExecutionCallableRunner(
           ^^^^^^^^^^^^^^^^^^^^^^^^
  File "/home/airflow/.local/lib/python3.12/site-packages/airflow/utils/operator_helpers.py", line 252, in run
    return self.func(*args, **kwargs)
           ^^^^^^^^^^^^^^^^^^^^^^^^^^
  File "/home/airflow/.local/lib/python3.12/site-packages/airflow/models/baseoperator.py", line 406, in wrapper
    return func(self, *args, **kwargs)
           ^^^^^^^^^^^^^^^^^^^^^^^^^^^
  File "/home/airflow/.local/lib/python3.12/site-packages/airflow/operators/python.py", line 238, in execute
    return_value = self.execute_callable()
                   ^^^^^^^^^^^^^^^^^^^^^^^
  File "/home/airflow/.local/lib/python3.12/site-packages/airflow/operators/python.py", line 256, in execute_callable
    return runner.run(*self.op_args, **self.op_kwargs)
           ^^^^^^^^^^^^^^^^^^^^^^^^^^^^^^^^^^^^^^^^^^^
  File "/home/airflow/.local/lib/python3.12/site-packages/airflow/utils/operator_helpers.py", line 252, in run
    return self.func(*args, **kwargs)
           ^^^^^^^^^^^^^^^^^^^^^^^^^^
  File "/opt/airflow/dags/Seoul_spark.py", line 127, in _geomerge_plot
    import geopandas as gpd
ModuleNotFoundError: No module named 'geopandas'
[2024-08-27T06:01:42.294+0000] {local_task_job_runner.py:261} INFO - Task exited with return code 1
[2024-08-27T06:01:42.360+0000] {taskinstance.py:3891} INFO - 0 downstream tasks scheduled from follow-on schedule check
[2024-08-27T06:01:42.382+0000] {local_task_job_runner.py:240} INFO - ::endgroup::
