[2024-08-27T05:54:59.169+0000] {local_task_job_runner.py:123} INFO - ::group::Pre task execution logs
[2024-08-27T05:54:59.257+0000] {taskinstance.py:2603} INFO - Dependencies all met for dep_context=non-requeueable deps ti=<TaskInstance: Spark.download_dataset_api manual__2024-08-27T05:54:50.770185+00:00 [queued]>
[2024-08-27T05:54:59.283+0000] {taskinstance.py:2603} INFO - Dependencies all met for dep_context=requeueable deps ti=<TaskInstance: Spark.download_dataset_api manual__2024-08-27T05:54:50.770185+00:00 [queued]>
[2024-08-27T05:54:59.285+0000] {taskinstance.py:2856} INFO - Starting attempt 1 of 1
[2024-08-27T05:54:59.333+0000] {taskinstance.py:2879} INFO - Executing <Task(BashOperator): download_dataset_api> on 2024-08-27 05:54:50.770185+00:00
[2024-08-27T05:54:59.353+0000] {logging_mixin.py:190} WARNING - /home/***/.local/lib/python3.12/site-packages/***/task/task_runner/standard_task_runner.py:70 DeprecationWarning: This process (pid=1125) is multi-threaded, use of fork() may lead to deadlocks in the child.
[2024-08-27T05:54:59.350+0000] {standard_task_runner.py:104} INFO - Running: ['***', 'tasks', 'run', 'Spark', 'download_dataset_api', 'manual__2024-08-27T05:54:50.770185+00:00', '--job-id', '245', '--raw', '--subdir', 'DAGS_FOLDER/Seoul_spark.py', '--cfg-path', '/tmp/tmpwxvlaebm']
[2024-08-27T05:54:59.359+0000] {standard_task_runner.py:72} INFO - Started process 1128 to run task
[2024-08-27T05:54:59.359+0000] {standard_task_runner.py:105} INFO - Job 245: Subtask download_dataset_api
[2024-08-27T05:54:59.505+0000] {task_command.py:467} INFO - Running <TaskInstance: Spark.download_dataset_api manual__2024-08-27T05:54:50.770185+00:00 [running]> on host 1c1d52fdfc5f
[2024-08-27T05:54:59.733+0000] {taskinstance.py:3122} INFO - Exporting env vars: AIRFLOW_CTX_DAG_OWNER='***' AIRFLOW_CTX_DAG_ID='Spark' AIRFLOW_CTX_TASK_ID='download_dataset_api' AIRFLOW_CTX_EXECUTION_DATE='2024-08-27T05:54:50.770185+00:00' AIRFLOW_CTX_TRY_NUMBER='1' AIRFLOW_CTX_DAG_RUN_ID='manual__2024-08-27T05:54:50.770185+00:00'
[2024-08-27T05:54:59.739+0000] {taskinstance.py:731} INFO - ::endgroup::
[2024-08-27T05:54:59.800+0000] {subprocess.py:63} INFO - Tmp dir root location: /tmp
[2024-08-27T05:54:59.805+0000] {subprocess.py:75} INFO - Running command: ['/usr/bin/bash', '-c', 'kaggle datasets download -d bappekim/air-pollution-in-seoul -p /opt/***/dags --unzip']
[2024-08-27T05:54:59.822+0000] {subprocess.py:86} INFO - Output:
[2024-08-27T05:54:59.827+0000] {subprocess.py:93} INFO - /usr/bin/bash: line 1: kaggle: command not found
[2024-08-27T05:54:59.828+0000] {subprocess.py:97} INFO - Command exited with return code 127
[2024-08-27T05:54:59.858+0000] {taskinstance.py:3301} ERROR - Task failed with exception
Traceback (most recent call last):
  File "/home/airflow/.local/lib/python3.12/site-packages/airflow/models/taskinstance.py", line 767, in _execute_task
    result = _execute_callable(context=context, **execute_callable_kwargs)
             ^^^^^^^^^^^^^^^^^^^^^^^^^^^^^^^^^^^^^^^^^^^^^^^^^^^^^^^^^^^^^
  File "/home/airflow/.local/lib/python3.12/site-packages/airflow/models/taskinstance.py", line 733, in _execute_callable
    return ExecutionCallableRunner(
           ^^^^^^^^^^^^^^^^^^^^^^^^
  File "/home/airflow/.local/lib/python3.12/site-packages/airflow/utils/operator_helpers.py", line 252, in run
    return self.func(*args, **kwargs)
           ^^^^^^^^^^^^^^^^^^^^^^^^^^
  File "/home/airflow/.local/lib/python3.12/site-packages/airflow/models/baseoperator.py", line 406, in wrapper
    return func(self, *args, **kwargs)
           ^^^^^^^^^^^^^^^^^^^^^^^^^^^
  File "/home/airflow/.local/lib/python3.12/site-packages/airflow/operators/bash.py", line 249, in execute
    raise AirflowException(
airflow.exceptions.AirflowException: Bash command failed. The command returned a non-zero exit code 127.
[2024-08-27T05:54:59.869+0000] {taskinstance.py:1225} INFO - Marking task as FAILED. dag_id=Spark, task_id=download_dataset_api, run_id=manual__2024-08-27T05:54:50.770185+00:00, execution_date=20240827T055450, start_date=20240827T055459, end_date=20240827T055459
[2024-08-27T05:54:59.900+0000] {taskinstance.py:340} INFO - ::group::Post task execution logs
[2024-08-27T05:54:59.902+0000] {standard_task_runner.py:124} ERROR - Failed to execute job 245 for task download_dataset_api (Bash command failed. The command returned a non-zero exit code 127.; 1128)
Traceback (most recent call last):
  File "/home/airflow/.local/lib/python3.12/site-packages/airflow/task/task_runner/standard_task_runner.py", line 117, in _start_by_fork
    ret = args.func(args, dag=self.dag)
          ^^^^^^^^^^^^^^^^^^^^^^^^^^^^^
  File "/home/airflow/.local/lib/python3.12/site-packages/airflow/cli/cli_config.py", line 49, in command
    return func(*args, **kwargs)
           ^^^^^^^^^^^^^^^^^^^^^
  File "/home/airflow/.local/lib/python3.12/site-packages/airflow/utils/cli.py", line 115, in wrapper
    return f(*args, **kwargs)
           ^^^^^^^^^^^^^^^^^^
  File "/home/airflow/.local/lib/python3.12/site-packages/airflow/cli/commands/task_command.py", line 483, in task_run
    task_return_code = _run_task_by_selected_method(args, _dag, ti)
                       ^^^^^^^^^^^^^^^^^^^^^^^^^^^^^^^^^^^^^^^^^^^^
  File "/home/airflow/.local/lib/python3.12/site-packages/airflow/cli/commands/task_command.py", line 256, in _run_task_by_selected_method
    return _run_raw_task(args, ti)
           ^^^^^^^^^^^^^^^^^^^^^^^
  File "/home/airflow/.local/lib/python3.12/site-packages/airflow/cli/commands/task_command.py", line 341, in _run_raw_task
    return ti._run_raw_task(
           ^^^^^^^^^^^^^^^^^
  File "/home/airflow/.local/lib/python3.12/site-packages/airflow/utils/session.py", line 97, in wrapper
    return func(*args, session=session, **kwargs)
           ^^^^^^^^^^^^^^^^^^^^^^^^^^^^^^^^^^^^^^
  File "/home/airflow/.local/lib/python3.12/site-packages/airflow/models/taskinstance.py", line 2995, in _run_raw_task
    return _run_raw_task(
           ^^^^^^^^^^^^^^
  File "/home/airflow/.local/lib/python3.12/site-packages/airflow/models/taskinstance.py", line 273, in _run_raw_task
    TaskInstance._execute_task_with_callbacks(
  File "/home/airflow/.local/lib/python3.12/site-packages/airflow/models/taskinstance.py", line 3149, in _execute_task_with_callbacks
    result = self._execute_task(context, task_orig)
             ^^^^^^^^^^^^^^^^^^^^^^^^^^^^^^^^^^^^^^
  File "/home/airflow/.local/lib/python3.12/site-packages/airflow/models/taskinstance.py", line 3173, in _execute_task
    return _execute_task(self, context, task_orig)
           ^^^^^^^^^^^^^^^^^^^^^^^^^^^^^^^^^^^^^^^
  File "/home/airflow/.local/lib/python3.12/site-packages/airflow/models/taskinstance.py", line 767, in _execute_task
    result = _execute_callable(context=context, **execute_callable_kwargs)
             ^^^^^^^^^^^^^^^^^^^^^^^^^^^^^^^^^^^^^^^^^^^^^^^^^^^^^^^^^^^^^
  File "/home/airflow/.local/lib/python3.12/site-packages/airflow/models/taskinstance.py", line 733, in _execute_callable
    return ExecutionCallableRunner(
           ^^^^^^^^^^^^^^^^^^^^^^^^
  File "/home/airflow/.local/lib/python3.12/site-packages/airflow/utils/operator_helpers.py", line 252, in run
    return self.func(*args, **kwargs)
           ^^^^^^^^^^^^^^^^^^^^^^^^^^
  File "/home/airflow/.local/lib/python3.12/site-packages/airflow/models/baseoperator.py", line 406, in wrapper
    return func(self, *args, **kwargs)
           ^^^^^^^^^^^^^^^^^^^^^^^^^^^
  File "/home/airflow/.local/lib/python3.12/site-packages/airflow/operators/bash.py", line 249, in execute
    raise AirflowException(
airflow.exceptions.AirflowException: Bash command failed. The command returned a non-zero exit code 127.
[2024-08-27T05:54:59.939+0000] {local_task_job_runner.py:261} INFO - Task exited with return code 1
[2024-08-27T05:54:59.987+0000] {taskinstance.py:3891} INFO - 0 downstream tasks scheduled from follow-on schedule check
[2024-08-27T05:54:59.997+0000] {local_task_job_runner.py:240} INFO - ::endgroup::
